{"uuid": "d50397f9-70d0-40ef-b1ba-ac1802c4bfb6", "children": ["488df9aa-4ebe-4119-a7e0-cadd519ed294", "d45e09a1-7635-4d94-8c9b-acae4f2607e7"], "befores": [{"name": "xunit_setup_class_fixture_Test_notice", "status": "broken", "statusDetails": {"message": "selenium.common.exceptions.WebDriverException: Message: unknown error: net::ERR_CONNECTION_TIMED_OUT\n  (Session info: chrome=94.0.4606.81)\n\n", "trace": "  File \"D:\\Python\\lib\\site-packages\\pluggy\\callers.py\", line 187, in _multicall\n    res = hook_impl.function(*args)\n  File \"D:\\Python\\lib\\site-packages\\_pytest\\fixtures.py\", line 1126, in pytest_fixture_setup\n    result = call_fixture_func(fixturefunc, request, kwargs)\n  File \"D:\\Python\\lib\\site-packages\\_pytest\\fixtures.py\", line 925, in call_fixture_func\n    fixture_result = next(generator)\n  File \"D:\\Python\\lib\\site-packages\\_pytest\\python.py\", line 811, in xunit_setup_class_fixture\n    _call_with_optional_argument(func, self.obj)\n  File \"D:\\Python\\lib\\site-packages\\_pytest\\python.py\", line 739, in _call_with_optional_argument\n    func(arg)\n  File \"D:\\Program Files\\JetBrains\\PyCharm Community Edition 2020.2\\pytest_allure\\testcase\\test_notice.py\", line 14, in setup_class\n    cls.driver.get('http://sqwytst.wt.com:14352/')\n  File \"D:\\Python\\lib\\site-packages\\selenium\\webdriver\\remote\\webdriver.py\", line 333, in get\n    self.execute(Command.GET, {'url': url})\n  File \"D:\\Python\\lib\\site-packages\\selenium\\webdriver\\remote\\webdriver.py\", line 321, in execute\n    self.error_handler.check_response(response)\n  File \"D:\\Python\\lib\\site-packages\\selenium\\webdriver\\remote\\errorhandler.py\", line 242, in check_response\n    raise exception_class(message, screen, stacktrace)\n"}, "start": 1638603351305, "stop": 1638603394706}], "start": 1638603351305, "stop": 1638603394751}